<?xml version="1.0"?><robot name="pepe">
	<link name="0">
		<visual>
			<geometry>
				<cylinder length="1.3210271354763845" radius="0.8549868949668232"/>
			</geometry>
		</visual>
		<collision>
			<geometry>
				<cylinder length="1.3210271354763845" radius="0.8549868949668232"/>
			</geometry>
		</collision>
		<inertial>
			<mass value="3.0337551554472775"/>
			<inertia ixx="0.03" iyy="0.03" izz="0.03" ixy="0" ixz="0" iyx="0"/>
		</inertial>
	</link>
	<link name="11">
		<visual>
			<geometry>
				<cylinder length="1.7966245945028012" radius="0.9489423247712325"/>
			</geometry>
		</visual>
		<collision>
			<geometry>
				<cylinder length="1.7966245945028012" radius="0.9489423247712325"/>
			</geometry>
		</collision>
		<inertial>
			<mass value="5.08261072143375"/>
			<inertia ixx="0.03" iyy="0.03" izz="0.03" ixy="0" ixz="0" iyx="0"/>
		</inertial>
	</link>
	<link name="22">
		<visual>
			<geometry>
				<cylinder length="1.3210271354763845" radius="0.7549868949668233"/>
			</geometry>
		</visual>
		<collision>
			<geometry>
				<cylinder length="1.3210271354763845" radius="0.7549868949668233"/>
			</geometry>
		</collision>
		<inertial>
			<mass value="2.3655952407784353"/>
			<inertia ixx="0.03" iyy="0.03" izz="0.03" ixy="0" ixz="0" iyx="0"/>
		</inertial>
	</link>
	<link name="13">
		<visual>
			<geometry>
				<cylinder length="1.7966245945028012" radius="0.9489423247712325"/>
			</geometry>
		</visual>
		<collision>
			<geometry>
				<cylinder length="1.7966245945028012" radius="0.9489423247712325"/>
			</geometry>
		</collision>
		<inertial>
			<mass value="5.08261072143375"/>
			<inertia ixx="0.03" iyy="0.03" izz="0.03" ixy="0" ixz="0" iyx="0"/>
		</inertial>
	</link>
	<link name="24">
		<visual>
			<geometry>
				<cylinder length="1.3210271354763845" radius="0.7549868949668233"/>
			</geometry>
		</visual>
		<collision>
			<geometry>
				<cylinder length="1.3210271354763845" radius="0.7549868949668233"/>
			</geometry>
		</collision>
		<inertial>
			<mass value="2.3655952407784353"/>
			<inertia ixx="0.03" iyy="0.03" izz="0.03" ixy="0" ixz="0" iyx="0"/>
		</inertial>
	</link>
	<joint name="11_to_0" type="revolute">
		<parent link="0"/>
		<child link="11"/>
		<axis xyz="1 0 0"/>
		<limit effort="1" upper="-3.1415" lower="3.1415" velocity="1"/>
		<origin rpy="7.267383642417107 2.2567124251757202 1.6841347499928716" xyz="0.29027910459329453 0.7997746468004846 0.27250180589683015"/>
	</joint>
	<joint name="22_to_11" type="revolute">
		<parent link="11"/>
		<child link="22"/>
		<axis xyz="0 1 0"/>
		<limit effort="1" upper="-3.1415" lower="3.1415" velocity="1"/>
		<origin rpy="6.923334363340418 3.5991304775359034 4.4871236248258555" xyz="0.9999 0.9999 0.9782963002248686"/>
	</joint>
	<joint name="13_to_0" type="revolute">
		<parent link="0"/>
		<child link="13"/>
		<axis xyz="1 0 0"/>
		<limit effort="1" upper="-3.1415" lower="3.1415" velocity="1"/>
		<origin rpy="10.90107546362566 2.2567124251757202 1.6841347499928716" xyz="0.29027910459329453 0.7997746468004846 0.27250180589683015"/>
	</joint>
	<joint name="24_to_13" type="revolute">
		<parent link="13"/>
		<child link="24"/>
		<axis xyz="0 1 0"/>
		<limit effort="1" upper="-3.1415" lower="3.1415" velocity="1"/>
		<origin rpy="6.923334363340418 3.5991304775359034 4.4871236248258555" xyz="0.9999 0.9999 0.9782963002248686"/>
	</joint>
</robot>
